<?xml version="1.0"?>
<!-- created with Phobos 1.0.1 "Capricious Choutengan" -->
  <robot name="omni_tratsah">

    <link name="back_left_wheel">
      <inertial>
        <origin xyz="0 0 0" rpy="0 0 0"/>
        <mass value="0.5"/>
        <inertia ixx="0.00044" ixy="0.00014" ixz="0" iyy="0.00044" iyz="0" izz="0.0003"/>
      </inertial>
      <visual name="back_left_wheel">
        <origin xyz="0 0 0" rpy="0 0 0"/>
        <geometry>
          <mesh filename="/home/teera/dev_ws/src/tratsah/meshes/dae/Torus.dae" scale="0.2 0.2 0.2"/>
        </geometry>
        <material name="Black"/>
      </visual>
      <collision name="back_left_wheel">
        <origin xyz="0 0 0" rpy="0 0 0"/>
        <geometry>
          <cylinder radius="0.25" length="0.1"/>
        </geometry>
      </collision>
    </link>

    <link name="back_right_wheel">
      <inertial>
        <origin xyz="0 0 0" rpy="0 0 0"/>
        <mass value="0.5"/>
        <inertia ixx="0.00044" ixy="-0.00014" ixz="0" iyy="0.00044" iyz="0" izz="0.0003"/>
      </inertial>
      <visual name="back_right_wheel">
        <origin xyz="0 0 0" rpy="0 3.14159 0"/>
        <geometry>
          <mesh filename="/home/teera/dev_ws/src/tratsah/meshes/dae/Torus.dae" scale="0.2 0.2 0.2"/>
        </geometry>
        <material name="Black"/>
      </visual>
      <collision name="back_right_wheel">
        <origin xyz="0 0 0" rpy="0 3.14159 0.7854"/>
        <geometry>
          <cylinder radius="0.25" length="0.1"/>
        </geometry>
      </collision>
    </link>

    <link name="base">
      <inertial>
        <origin xyz="0 0 0" rpy="0 0 0"/>
        <mass value="5.0"/>
        <inertia ixx="0.13052" ixy="0" ixz="0" iyy="0.13052" iyz="0" izz="0.55506"/>
      </inertial>
      <visual name="Base">
        <origin xyz="0 0 0" rpy="0 0 0"/>
        <geometry>
          <mesh filename="/home/teera/dev_ws/src/tratsah/meshes/dae/Cube.001.dae" scale="0.5 0.5 0.1"/>
        </geometry>
        <material name="Green"/>
      </visual>
      <collision name="Base">
        <origin xyz="0 0 0" rpy="0 0 0"/>
        <geometry>
          <box size="0.81613 0.81613 0.2"/>
        </geometry>
      </collision>
    </link>

    <link name="front_left_wheel">
      <inertial>
        <origin xyz="0 0 0" rpy="0 0 0"/>
        <mass value="0.5"/>
        <inertia ixx="0.00044" ixy="-0.00014" ixz="0" iyy="0.00044" iyz="0" izz="0.0003"/>
      </inertial>
      <visual name="front_left_wheel">
        <origin xyz="0 0 0" rpy="0 3.14159 0"/>
        <geometry>
          <mesh filename="/home/teera/dev_ws/src/tratsah/meshes/dae/Torus.dae" scale="0.2 0.2 0.2"/>
        </geometry>
        <material name="Black"/>
      </visual>
      <collision name="front_left_wheel">
        <origin xyz="0 0 0" rpy="0 3.14159 0"/>
        <geometry>
          <cylinder radius="0.25" length="0.1"/>
        </geometry>
      </collision>
    </link>

    <link name="front_right_wheel">
      <inertial>
        <origin xyz="0 0 0" rpy="0 0 0"/>
        <mass value="0.5"/>
        <inertia ixx="0.00044" ixy="0.00014" ixz="0" iyy="0.00044" iyz="0" izz="0.0003"/>
      </inertial>
      <visual name="front_right_wheel">
        <origin xyz="0 0 0" rpy="0 0 0"/>
        <geometry>
          <mesh filename="/home/teera/dev_ws/src/tratsah/meshes/dae/Torus.dae" scale="0.2 0.2 0.2"/>
        </geometry>
        <material name="Black"/>
      </visual>
      <collision name="front_right_wheel">
        <origin xyz="0 0 0" rpy="0 0 0"/>
        <geometry>
          <cylinder radius="0.25" length="0.1"/>
        </geometry>
      </collision>
    </link>

    <joint name="back_left_motor" type="continuous">
      <origin xyz="-0.45 -0.45 0" rpy="1.5708 0 -0.7854"/>
      <parent link="base"/>
      <child link="back_left_wheel"/>
      <axis xyz="0 0 1.0"/>
      <limit effort="2.4" velocity="1.0"/>
    </joint>

    <joint name="back_right_motor" type="continuous">
      <origin xyz="0.45 -0.45 0" rpy="1.5708 0 0.7854"/>
      <parent link="base"/>
      <child link="back_right_wheel"/>
      <axis xyz="0 0 1.0"/>
      <limit effort="2.4" velocity="1.0"/>
    </joint>

    <joint name="front_left_motor" type="continuous">
      <origin xyz="-0.45 0.45 0" rpy="1.5708 0 -2.35619"/>
      <parent link="base"/>
      <child link="front_left_wheel"/>
      <axis xyz="0 0 1.0"/>
      <limit effort="2.4" velocity="1.0"/>
    </joint>

    <joint name="front_right_motor" type="continuous">
      <origin xyz="0.45 0.45 0" rpy="1.5708 0 2.35619"/>
      <parent link="base"/>
      <child link="front_right_wheel"/>
      <axis xyz="0 0 1.0"/>
      <limit effort="2.4" velocity="1.0"/>
    </joint>

    <material name="Black">
      <color rgba="0.00887 0.00887 0.00887 1.0"/>
    </material>

    <material name="Green">
      <color rgba="0.02552 0.35173 0.00685 1.0"/>
    </material>

  <link name="imu">
      <inertial>
        <mass value="0.1"/>
        <inertia ixx="1.0" ixy="0" ixz="0" iyy="1.0" iyz="0" izz="1.0"/>
      </inertial>
    </link>
    <joint name="cart_to_imu" type="fixed">
      <origin xyz="0.0 0.0 0.0"/>
      <parent link="base"/>
      <child link="imu"/>
      <dynamics damping="0.0" friction="0.0"/>
    </joint>

    <gazebo reference="imu">
      <sensor name="cart_imu_sensor" type="imu">
        <always_on>1</always_on>
        <update_rate>10.0</update_rate>
      </sensor>
    </gazebo>

    <ros2_control name="GazeboSystem" type="system">
      <hardware>
        <plugin>gazebo_ros2_control/GazeboSystem</plugin>
      </hardware>
      <joint name="front_left_motor">
        <command_interface name="velocity">
          <param name="min">-10</param>
          <param name="max">10</param>
        </command_interface>
        <state_interface name="position"/>
        <state_interface name="velocity"/>
        <state_interface name="effort"/>
      </joint>
      <joint name="front_right_motor">
        <command_interface name="velocity">
          <param name="min">-10</param>
          <param name="max">10</param>
        </command_interface>
        <state_interface name="position"/>
        <state_interface name="velocity"/>
        <state_interface name="effort"/>
      </joint>
      <joint name="back_left_motor">
        <command_interface name="velocity">
          <param name="min">-10</param>
          <param name="max">10</param>
        </command_interface>
        <state_interface name="position"/>
        <state_interface name="velocity"/>
        <state_interface name="effort"/>
      </joint>
      <joint name="back_right_motor">
        <command_interface name="velocity">
          <param name="min">-10</param>
          <param name="max">10</param>
        </command_interface>
        <state_interface name="position"/>
        <state_interface name="velocity"/>
        <state_interface name="effort"/>
      </joint>
      <sensor name="cart_imu_sensor">
        <state_interface name="orientation.x"/>
        <state_interface name="orientation.y"/>
        <state_interface name="orientation.z"/>
        <state_interface name="orientation.w"/>
        <state_interface name="angular_velocity.x"/>
        <state_interface name="angular_velocity.y"/>
        <state_interface name="angular_velocity.z"/>
        <state_interface name="linear_acceleration.x"/>
        <state_interface name="linear_acceleration.y"/>
        <state_interface name="linear_acceleration.z"/>
      </sensor>
    </ros2_control>

    <gazebo>
      <plugin filename="libgazebo_ros2_control.so" name="gazebo_ros2_control">
        <parameters>/home/teera/dev_ws/src/tratsah/config/omni_base_controller_velocity.yaml</parameters>
      </plugin>
    </gazebo>

  </robot>
